<mujoco>
	<body mocap="true" name="robot0:mocap" pos="0 0 0">
		<geom conaffinity="0" contype="0" pos="0 0 0" rgba="0 0.5 0 0.0" size="0.005 0.005 0.005" type="box"></geom>
	</body>

    <body name="base_link" pos="0. 0 0.3">
        <geom type="box" size="0.15 0.15 0.3" rgba="1 1 1 1" contype="0" conaffinity="0"></geom>
    
        <body name="panda_link0" childclass="panda" pos="0.05 0 0.3">
            <inertial pos="0 0 0" quat="1 0 0 0" mass="3.06" diaginertia="0.3 0.3 0.3" />
            <geom class="visual" mesh="link0_visual"/>
            <!-- <geom class="collision" mesh="link0_collision"/> -->

            <body name="panda_link1" pos="0 0 0.333">
                <inertial pos="3.875e-03 2.081e-03 -0.1750" quat="1 0 0 0" mass="4.970684" fullinertia="7.0337e-01 7.0661e-01 9.1170e-03 -1.3900e-04 6.7720e-03 1.9169e-02" />
                <joint name="panda_joint1" range="-2.8973 2.8973"/>
                <geom class="visual" mesh="link1_visual"/>
                <!-- <geom class="collision" mesh="link1_collision"/> -->

                <body name="panda_link2" pos="0 0 0" quat="0.707107 -0.707107 0 0">
                    <inertial pos="-3.141e-03 -2.872e-02 3.495e-03" quat="1 0 0 0" mass="0.646926" fullinertia="7.9620e-03 2.8110e-02 2.5995e-02 -3.9250e-03 1.0254e-02 7.0400e-04" />
                    <joint name="panda_joint2" range="-1.7628 1.7628"/>
                    <geom class="visual" mesh="link2_visual"/>
                    <!-- <geom class="collision" mesh="link2_collision"/> -->

                    <body name="panda_link3" pos="0 -0.316 0" quat="0.707107 0.707107 0 0">
                        <inertial pos="2.7518e-02 3.9252e-02 -6.6502e-02" quat="1 0 0 0" mass="3.228604" fullinertia="3.7242e-02 3.6155e-02 1.0830e-02 -4.7610e-03 -1.1396e-02 -1.2805e-02" />
                        <joint name="panda_joint3" range="-2.8973 2.8973"/>
                        <geom class="visual" mesh="link3_visual"/>
                        <!-- <geom class="collision" mesh="link3_collision"/> -->

                        <body name="panda_link4" pos="0.0825 0 0" quat="0.707107 0.707107 0 0">
                            <inertial pos="-5.317e-02 1.04419e-01 2.7454e-02" quat="1 0 0 0" mass="3.587895" fullinertia="2.5853e-02 1.9552e-02 2.8323e-02 7.7960e-03 -1.3320e-03 8.6410e-03" />
                            <joint name="panda_joint4" range="-3.0718 -0.4"/>
                            <geom class="visual" mesh="link4_visual"/>
                            <!-- <geom class="collision" mesh="link4_collision"/> -->

                            <body name="panda_link5" pos="-0.0825 0.384 0" quat="0.707107 -0.707107 0 0">
                                <inertial pos="-1.1953e-02 4.1065e-02 -3.8437e-02" quat="1 0 0 0" mass="1.225946" fullinertia="3.5549e-02 2.9474e-02 8.6270e-03 -2.1170e-03 -4.0370e-03 2.2900e-04" />
                                <joint name="panda_joint5" range="-2.8973 2.8973"/>
                                <geom class="visual" mesh="link5_visual"/>
                                <!-- <geom class="collision" mesh="link5_collision"/> -->

                                <body name="panda_link6" pos="0 0 0" quat="0.707107 0.707107 0 0">
                                    <inertial pos="6.0149e-02 -1.4117e-02 -1.0517e-02" quat="1 0 0 0" mass="1.666555" fullinertia="1.9640e-03 4.3540e-03 5.4330e-03 1.0900e-04 -1.1580e-03 3.4100e-04" />
                                    <joint name="panda_joint6" range="-1.6573 2.1127"/>
                                    <geom class="visual" mesh="link6_visual"/>
                                    <!-- <geom class="collision" mesh="link6_collision"/> -->

                                    <body name="panda_link7" pos="0.088 0 0" euler='1.57 0 0.'>
                                        <inertial pos="1.0517e-02 -4.252e-03 6.1597e-02" quat="1 0 0 0" mass="7.35522e-01" fullinertia="1.2516e-02 1.0027e-02 4.8150e-03 -4.2800e-04 -1.1960e-03 -7.4100e-04" />
                                        <joint name="panda_joint7" range="-2.8973 2.8973"/>
                                        <geom class="visual" mesh="link7_visual" rgba="0.2 0.2 0.2 1"/>
                                        <site name="conx" pos="0.0707 0.0707 0.088" size="0.1 0.004 0.004" rgba="1 0 0 1" type="box" euler='0 0 0.785'></site>
                                        <site name="cony" pos="-0.0707 0.0707 0.088" size="0.004 0.1 0.004" rgba="0 1 0 1" type="box" euler='0 0 0.785'></site>
                                        <site name="conz" pos="0 0 0.1255" size="0.004 0.004 0.1" rgba="0 0 1 1" type="box" euler='0 0 0.785'></site>

                                        <!-- <geom class="collision" mesh="link7_collision"/> -->

                                        <body name="robot0:gripper_link" pos="0 0 0.107" euler="0 0 -0.785">
                                            <inertial pos="0 0 0" euler="0 0 0" mass="0.68" diaginertia="0.1 0.1 0.1" />
                                            <geom class="visual" mesh="hand_visual" rgba="0.2 0.2 0.2 1"/>
                                            <geom class="collision" mesh="hand_collision"/>

                                            <body name="robot0:virtual_weld_link" euler="-1.5708 0 -1.5708" pos="0 0 0.1"></body>

                                            <body childclass="robot0:Finger" name="robot0:r_gripper_finger_link" pos="0 0.0159 0.1" euler="0 1.5708 0">
                                                <inertial diaginertia="0.1 0.1 0.1" mass="4" pos="-0.01 0 0"></inertial>
                                                <joint axis="0 1 0" name="robot0:r_gripper_finger_joint" range="0 0.05"></joint>
                                                <geom pos="0 -0.008 0" size="0.0385 0.007 0.0135" type="box" name="robot0:r_gripper_finger_link" rgba="0.2 0.2 0.2 1" material="robot0:finger_mat" condim="4" friction="1 0.05 0.01"></geom>
                                            </body>
                                            <body childclass="robot0:Finger" name="robot0:l_gripper_finger_link" pos="0 -0.0159 0.1" euler="0 1.5708 0">
                                                <inertial diaginertia="0.1 0.1 0.1" mass="4" pos="-0.01 0 0"></inertial>
                                                <joint axis="0 -1 0" name="robot0:l_gripper_finger_joint" range="0 0.05"></joint>
                                                <geom pos="0 0.008 0" size="0.0385 0.007 0.0135" type="box" name="robot0:l_gripper_finger_link" rgba="0.2 0.2 0.2 1" material="robot0:finger_mat" condim="4" friction="1 0.05 0.01"></geom>
                                            </body>
                                            <site name="robot0:grip" pos="0 0 0" rgba="0 0 0 0" size="0.02 0.02 0.02"></site>
                                        </body>
                                    </body>
                                </body>
                            </body>
                        </body>
                    </body>
                </body>
            </body>
        </body>
    </body>
</mujoco>

