<!-- See LICENSE.md for legal notices. LICENSE.md must be kept together with this file. -->
<mujoco>
    <body mocap="true" name="robot0:mocap" pos="0 0 0">
		<geom conaffinity="0" contype="0" pos="0 0 0" rgba="0 0.5 0 0.7" size="0.005 0.005 0.005" type="box"></geom>
		<geom conaffinity="0" contype="0" pos="0 0 0" rgba="0 0.5 0 0.1" size="1 0.005 0.005" type="box"></geom>
		<geom conaffinity="0" contype="0" pos="0 0 0" rgba="0 0.5 0 0.1" size="0.005 1 0.001" type="box"></geom>
		<geom conaffinity="0" contype="0" pos="0 0 0" rgba="0 0.5 0 0.1" size="0.005 0.005 1" type="box"></geom>
	</body>
	<body childclass="robot0:fetch" name="robot0:base_link" pos="0.2869 0.2641 0">
		<joint armature="0.0001" axis="1 0 0" damping="1e+11" name="robot0:slide0" pos="0 0 0" type="slide"></joint>
		<joint armature="0.0001" axis="0 1 0" damping="1e+11" name="robot0:slide1" pos="0 0 0" type="slide"></joint>
		<joint armature="0.0001" axis="0 0 1" damping="1e+11" name="robot0:slide2" pos="0 0 0" type="slide"></joint>
		<inertial diaginertia="1.2869 1.2236 0.9868" mass="70.1294" pos="-0.0036 0 0.0014" quat="0.7605 -0.0133 -0.0061 0.6491"></inertial>
		<geom mesh="robot0:base_link" name="robot0:base_link" material="robot0:base_mat" class="robot0:grey"></geom>
		<body name="robot0:torso_lift_link" pos="-0.0869 0 0.3774">
			<inertial diaginertia="0.3365 0.3354 0.0943" mass="10.7796" pos="-0.0013 -0.0009 0.2935" quat="0.9993 -0.0006 0.0336 0.0185"></inertial>
			<joint axis="0 0 1" damping="1e+07" name="robot0:torso_lift_joint" range="0.0386 0.3861" type="slide"></joint>
			<geom mesh="robot0:torso_lift_link" name="robot0:torso_lift_link" material="robot0:torso_mat"></geom>
			<body name="robot0:head_pan_link" pos="0.0531 0 0.603">
				<inertial diaginertia="0.0185 0.0128 0.0095" mass="2.2556" pos="0.0321 0.0161 0.039" quat="0.5148 0.5451 -0.453 0.4823"></inertial>
				<joint axis="0 0 1" name="robot0:head_pan_joint"></joint>
				<geom mesh="robot0:head_pan_link" name="robot0:head_pan_link" material="robot0:head_mat" class="robot0:grey"></geom>
				<body name="robot0:head_tilt_link" pos="0.1425 0 0.058">
					<inertial diaginertia="0.0063 0.0059 0.0014" mass="0.9087" pos="0.0081 0.0025 0.0113" quat="0.6458 0.66 -0.274 0.2689"></inertial>
					<joint axis="0 1 0" damping="1000" name="robot0:head_tilt_joint" ref="0.06"></joint>
					<geom mesh="robot0:head_tilt_link" name="robot0:head_tilt_link" material="robot0:head_mat" class="robot0:blue"></geom>
					<body name="robot0:head_camera_link" pos="0.055 0 0.0225">
						<inertial diaginertia="0 0 0" mass="0" pos="0.055 0 0.0225"></inertial>
						<body name="robot0:head_camera_rgb_frame" pos="0 0.02 0">
							<inertial diaginertia="0 0 0" mass="0" pos="0 0.02 0"></inertial>
							<body name="robot0:head_camera_rgb_optical_frame" pos="0 0 0" quat="0.5 -0.5 0.5 -0.5">
								<inertial diaginertia="0 0 0" mass="0" pos="0 0 0" quat="0.5 -0.5 0.5 -0.5"></inertial>
								<camera euler="3.1415 0 0" fovy="50" name="head_camera_rgb" pos="0 0 0"></camera>
							</body>
						</body>
						<body name="robot0:head_camera_depth_frame" pos="0 0.045 0">
							<inertial diaginertia="0 0 0" mass="0" pos="0 0.045 0"></inertial>
							<body name="robot0:head_camera_depth_optical_frame" pos="0 0 0" quat="0.5 -0.5 0.5 -0.5">
								<inertial diaginertia="0 0 0" mass="0" pos="0 0 0" quat="0.5 -0.5 0.5 -0.5"></inertial>
							</body>
						</body>
					</body>
				</body>
			</body>
			<body name="robot0:shoulder_pan_link" pos="0.1195 0 0.3486">
				<inertial diaginertia="0.009 0.0086 0.0041" mass="2.5587" pos="0.0927 -0.0056 0.0564" quat="-0.1364 0.7624 -0.1562 0.613"></inertial>
				<joint axis="0 0 1" name="robot0:shoulder_pan_joint"></joint>
				<geom mesh="robot0:shoulder_pan_link" name="robot0:shoulder_pan_link" material="robot0:arm_mat"></geom>
				<body name="robot0:shoulder_lift_link" pos="0.117 0 0.06">
					<inertial diaginertia="0.0116 0.0112 0.0023" mass="2.6615" pos="0.1432 0.0072 -0.0001" quat="0.4382 0.4382 0.555 0.555"></inertial>
					<joint axis="0 1 0" name="robot0:shoulder_lift_joint"></joint>
					<geom mesh="robot0:shoulder_lift_link" name="robot0:shoulder_lift_link" material="robot0:arm_mat" class="robot0:blue"></geom>
					<body name="robot0:upperarm_roll_link" pos="0.219 0 0">
						<inertial diaginertia="0.0047 0.0045 0.0019" mass="2.3311" pos="0.1165 0.0014 0" quat="-0.0136 0.707 0.0136 0.707"></inertial>
						<joint axis="1 0 0" limited="false" name="robot0:upperarm_roll_joint"></joint>
						<geom mesh="robot0:upperarm_roll_link" name="robot0:upperarm_roll_link" material="robot0:arm_mat"></geom>
						<body name="robot0:elbow_flex_link" pos="0.133 0 0">
							<inertial diaginertia="0.0086 0.0084 0.002" mass="2.1299" pos="0.1279 0.0073 0" quat="0.4332 0.4332 0.5589 0.5589"></inertial>
							<joint axis="0 1 0" name="robot0:elbow_flex_joint"></joint>
							<geom mesh="robot0:elbow_flex_link" name="robot0:elbow_flex_link" material="robot0:arm_mat" class="robot0:blue"></geom>
							<body name="robot0:forearm_roll_link" pos="0.197 0 0">
								<inertial diaginertia="0.0035 0.0031 0.0015" mass="1.6563" pos="0.1097 -0.0266 0" quat="-0.0715 0.7035 0.0715 0.7035"></inertial>
								<joint armature="2.7538" axis="1 0 0" damping="3.5247" frictionloss="0" limited="false" name="robot0:forearm_roll_joint" stiffness="10"></joint>
								<geom mesh="robot0:forearm_roll_link" name="robot0:forearm_roll_link" material="robot0:arm_mat"></geom>
								<body name="robot0:wrist_flex_link" pos="0.1245 0 0">
									<inertial diaginertia="0.0042 0.0042 0.0018" mass="1.725" pos="0.0882 0.0009 -0.0001" quat="0.4895 0.4895 0.5103 0.5103"></inertial>
									<joint axis="0 1 0" name="robot0:wrist_flex_joint"></joint>
									<geom mesh="robot0:wrist_flex_link" name="robot0:wrist_flex_link" material="robot0:arm_mat" class="robot0:blue"></geom>
									<body name="robot0:wrist_roll_link" pos="0.1385 0 0">
										<inertial diaginertia="0.0001 0.0001 0.0001" mass="0.1354" pos="0.0095 0.0004 -0.0002"></inertial>
										<joint axis="1 0 0" limited="false" name="robot0:wrist_roll_joint"></joint>
										<geom mesh="robot0:wrist_roll_link" name="robot0:wrist_roll_link" material="robot0:arm_mat"></geom>
										<body euler="0 0 0" name="robot0:gripper_link" pos="0.1664 0 0">

                                            <!-- Shadow hand begin -->
                                            <body name="robot0:hand_mount" pos="-0.25 0.0 0." euler="1.5707 1.5707 0">
                                                <inertial mass="0.1" pos="0 0 0" diaginertia="0.001 0.001 0.001"></inertial>
                                                <body childclass="robot0:asset_class" name="robot0:forearm" pos="0 0.01 0" euler="0 0 0">
                                                    <inertial pos="0.001 -0.002 0.29" quat="0.982 -0.016 0 -0.188" mass="4" diaginertia="0.01 0.01 0.0075"></inertial>
                                                    <geom class="robot0:D_Vizual" pos="0 0.01 0.04" name="robot0:V_forearm" mesh="robot0:forearm" euler="0 0 1.57"></geom>
                                                    <geom class="robot0:DC_Hand" name="robot0:C_forearm" type="mesh" mesh="robot0:forearm_cvx" pos="0 0.01 0.04" euler="0 0 1.57" rgba="0.4 0.5 0.6 0.7"></geom>
                                                    <body name="robot0:wrist" pos="0 0 0.256">
                                                        <inertial pos="0.003 0 0.016" quat="0.504 0.496 0.495 0.504" mass="0.3" diaginertia="0.001 0.001 0.001"></inertial>
                                                        <joint name="robot0:WRJ1" type="hinge" pos="0 0 0" axis="0 1 0" range="-0.489 0.14" damping="0.5" armature="0.005" user="1123"></joint>
                                                        <geom class="robot0:D_Vizual" name="robot0:V_wrist" mesh="robot0:wrist"></geom>
                                                        <geom class="robot0:DC_Hand" name="robot0:C_wrist" type="capsule" pos="0 0 0" quat="0.707 0.707 0 0" size="0.015 0.01" rgba="0.4 0.5 0.6 0.1"></geom>
                                                        <body name="robot0:palm" pos="0 0 0.034">
                                                            <inertial pos="0.006 0 0.036" quat="0.716 0.044 0.075 0.693" mass="0.3" diaginertia="0.001 0.001 0.001"></inertial>
                                                            <joint name="robot0:WRJ0" type="hinge" pos="0 0 0" axis="1 0 0" range="-0.698 0.489" damping="0.5" armature="0.005" user="1122"></joint>
                                                            <geom class="robot0:D_Vizual" name="robot0:V_palm" mesh="robot0:palm"></geom>
                                                            <geom class="robot0:DC_Hand" name="robot0:C_palm0" type="box" pos="0.011 0 0.038" size="0.032 0.0111 0.049" rgba="0.4 0.5 0.6 0.1"></geom>
                                                            <geom class="robot0:DC_Hand" name="robot0:C_palm1" type="box" pos="-0.032 0 0.014" size="0.011 0.0111 0.025" rgba="0.4 0.5 0.6 0.1"></geom>
                                                            <body name="robot0:ffknuckle" pos="0.033 0 0.095">
                                                                <inertial pos="0 0 0" quat="0.52 0.854 0.006 -0.003" mass="0.008" diaginertia="1e-05 1e-05 1e-05"></inertial>
                                                                <joint name="robot0:FFJ3" type="hinge" pos="0 0 0" axis="0 1 0" range="-0.349 0.349" user="1103"></joint>
                                                                <geom class="robot0:D_Vizual" name="robot0:V_ffknuckle" mesh="robot0:knuckle"></geom>
                                                                <body name="robot0:ffproximal" pos="0 0 0">
                                                                    <inertial pos="0 0 0.023" quat="0.707 -0.004 0.004 0.707" mass="0.014" diaginertia="1e-05 1e-05 1e-05"></inertial>
                                                                    <joint name="robot0:FFJ2" type="hinge" pos="0 0 0" axis="1 0 0" range="0 1.571" user="1102"></joint>
                                                                    <geom class="robot0:D_Vizual" name="robot0:V_ffproximal" mesh="robot0:F3"></geom>
                                                                    <geom class="robot0:DC_Hand" name="robot0:C_ffproximal" type="capsule" pos="0 0 0.0225" size="0.01 0.0225"></geom>
                                                                    <body name="robot0:ffmiddle" pos="0 0 0.045">
                                                                        <inertial pos="0 0 0.011" quat="0.707 0 0 0.707" mass="0.012" diaginertia="1e-05 1e-05 1e-05"></inertial>
                                                                        <joint name="robot0:FFJ1" type="hinge" pos="0 0 0" axis="1 0 0" range="0 1.571" user="1101"></joint>
                                                                        <geom class="robot0:D_Vizual" name="robot0:V_ffmiddle" mesh="robot0:F2"></geom>
                                                                        <geom class="robot0:DC_Hand" name="robot0:C_ffmiddle" type="capsule" pos="0 0 0.0125" size="0.00805 0.0125"></geom>
                                                                        <body name="robot0:ffdistal" pos="0 0 0.025">
                                                                            <inertial pos="0 0 0.015" quat="0.707 -0.003 0.003 0.707" mass="0.01" diaginertia="1e-05 1e-05 1e-05"></inertial>
                                                                            <joint name="robot0:FFJ0" type="hinge" pos="0 0 0" axis="1 0 0" range="0 1.571" user="1100"></joint>
                                                                            <geom class="robot0:D_Vizual" name="robot0:V_ffdistal" pos="0 0 0.001" mesh="robot0:F1"></geom>
                                                                            <geom class="robot0:DC_Hand" name="robot0:C_ffdistal" type="capsule" pos="0 0 0.012" size="0.00705 0.012" condim="4"></geom>
                                                                            <site name="robot0:S_fftip" pos="0 0 0.026" group="3"></site>
                                                                            <site class="robot0:D_Touch" name="robot0:Tch_fftip"></site>
                                                                        </body>
                                                                    </body>
                                                                </body>
                                                            </body>
                                                            <body name="robot0:mfknuckle" pos="0.011 0 0.099">
                                                                <inertial pos="0 0 0" quat="0.52 0.854 0.006 -0.003" mass="0.008" diaginertia="1e-05 1e-05 1e-05"></inertial>
                                                                <joint name="robot0:MFJ3" type="hinge" pos="0 0 0" axis="0 1 0" range="-0.349 0.349" user="1107"></joint>
                                                                <geom class="robot0:D_Vizual" name="robot0:V_mfknuckle" mesh="robot0:knuckle"></geom>
                                                                <body name="robot0:mfproximal" pos="0 0 0">
                                                                    <inertial pos="0 0 0.023" quat="0.707 -0.004 0.004 0.707" mass="0.014" diaginertia="1e-05 1e-05 1e-05"></inertial>
                                                                    <joint name="robot0:MFJ2" type="hinge" pos="0 0 0" axis="1 0 0" range="0 1.571" user="1106"></joint>
                                                                    <geom class="robot0:D_Vizual" name="robot0:V_mfproximal" mesh="robot0:F3"></geom>
                                                                    <geom class="robot0:DC_Hand" name="robot0:C_mfproximal" type="capsule" pos="0 0 0.0225" size="0.01 0.0225"></geom>
                                                                    <body name="robot0:mfmiddle" pos="0 0 0.045">
                                                                        <inertial pos="0 0 0.012" quat="0.707 0 0 0.707" mass="0.012" diaginertia="1e-05 1e-05 1e-05"></inertial>
                                                                        <joint name="robot0:MFJ1" type="hinge" pos="0 0 0" axis="1 0 0" range="0 1.571" user="1105"></joint>
                                                                        <geom class="robot0:D_Vizual" name="robot0:V_mfmiddle" mesh="robot0:F2"></geom>
                                                                        <geom class="robot0:DC_Hand" name="robot0:C_mfmiddle" type="capsule" pos="0 0 0.0125" size="0.00805 0.0125"></geom>
                                                                        <body name="robot0:mfdistal" pos="0 0 0.025">
                                                                            <inertial pos="0 0 0.015" quat="0.707 -0.003 0.003 0.707" mass="0.01" diaginertia="1e-05 1e-05 1e-05"></inertial>
                                                                            <joint name="robot0:MFJ0" type="hinge" pos="0 0 0" axis="1 0 0" range="0 1.571" user="1104"></joint>
                                                                            <geom class="robot0:D_Vizual" name="robot0:V_mfdistal" mesh="robot0:F1"></geom>
                                                                            <geom class="robot0:DC_Hand" name="robot0:C_mfdistal" type="capsule" pos="0 0 0.012" size="0.00705 0.012" condim="4"></geom>
                                                                            <site name="robot0:S_mftip" pos="0 0 0.026" group="3"></site>
                                                                            <site class="robot0:D_Touch" name="robot0:Tch_mftip"></site>
                                                                        </body>
                                                                    </body>
                                                                </body>
                                                            </body>
                                                            <body name="robot0:rfknuckle" pos="-0.011 0 0.095">
                                                                <inertial pos="0 0 0" quat="0.52 0.854 0.006 -0.003" mass="0.008" diaginertia="1e-05 1e-05 1e-05"></inertial>
                                                                <joint name="robot0:RFJ3" type="hinge" pos="0 0 0" axis="0 1 0" range="-0.349 0.349" user="1111"></joint>
                                                                <geom class="robot0:D_Vizual" name="robot0:V_rfknuckle" mesh="robot0:knuckle"></geom>
                                                                <body name="robot0:rfproximal" pos="0 0 0">
                                                                    <inertial pos="0 0 0.023" quat="0.707 -0.004 0.004 0.707" mass="0.014" diaginertia="1e-05 1e-05 1e-05"></inertial>
                                                                    <joint name="robot0:RFJ2" type="hinge" pos="0 0 0" axis="1 0 0" range="0 1.571" user="1110"></joint>
                                                                    <geom class="robot0:D_Vizual" name="robot0:V_rfproximal" mesh="robot0:F3"></geom>
                                                                    <geom class="robot0:DC_Hand" name="robot0:C_rfproximal" type="capsule" pos="0 0 0.0225" size="0.01 0.0225"></geom>
                                                                    <body name="robot0:rfmiddle" pos="0 0 0.045">
                                                                        <inertial pos="0 0 0.012" quat="0.707 0 0 0.707" mass="0.012" diaginertia="1e-05 1e-05 1e-05"></inertial>
                                                                        <joint name="robot0:RFJ1" type="hinge" pos="0 0 0" axis="1 0 0" range="0 1.571" user="1109"></joint>
                                                                        <geom class="robot0:D_Vizual" name="robot0:V_rfmiddle" mesh="robot0:F2"></geom>
                                                                        <geom class="robot0:DC_Hand" name="robot0:C_rfmiddle" type="capsule" pos="0 0 0.0125" size="0.00805 0.0125"></geom>
                                                                        <body name="robot0:rfdistal" pos="0 0 0.025">
                                                                            <inertial pos="0 0 0.015" quat="0.707 -0.003 0.003 0.707" mass="0.01" diaginertia="1e-05 1e-05 1e-05"></inertial>
                                                                            <joint name="robot0:RFJ0" type="hinge" pos="0 0 0" axis="1 0 0" range="0 1.571" user="1108"></joint>
                                                                            <geom class="robot0:D_Vizual" name="robot0:V_rfdistal" mesh="robot0:F1" pos="0 0 0.001"></geom>
                                                                            <geom class="robot0:DC_Hand" name="robot0:C_rfdistal" type="capsule" pos="0 0 0.012" size="0.00705 0.012" condim="4"></geom>
                                                                            <site name="robot0:S_rftip" pos="0 0 0.026" group="3"></site>
                                                                            <site class="robot0:D_Touch" name="robot0:Tch_rftip"></site>
                                                                        </body>
                                                                    </body>
                                                                </body>
                                                            </body>
                                                            <body name="robot0:lfmetacarpal" pos="-0.017 0 0.044">
                                                                <inertial pos="-0.014 0.001 0.014" quat="0.709 -0.092 -0.063 0.696" mass="0.075" diaginertia="1e-05 1e-05 1e-05"></inertial>
                                                                <joint name="robot0:LFJ4" type="hinge" pos="0 0 0" axis="0.571 0 0.821" range="0 0.785" user="1116"></joint>
                                                                <geom class="robot0:D_Vizual" name="robot0:V_lfmetacarpal" pos="-0.016 0 -0.023" mesh="robot0:lfmetacarpal"></geom>
                                                                <geom class="robot0:DC_Hand" name="robot0:C_lfmetacarpal" type="box" pos="-0.0165 0 0.01" size="0.0095 0.0111 0.025" rgba="0.4 0.5 0.6 0.2"></geom>
                                                                <body name="robot0:lfknuckle" pos="-0.017 0 0.044">
                                                                    <inertial pos="0 0 0" quat="0.52 0.854 0.006 -0.003" mass="0.008" diaginertia="1e-05 1e-05 1e-05"></inertial>
                                                                    <joint name="robot0:LFJ3" type="hinge" pos="0 0 0" axis="0 1 0" range="-0.349 0.349" user="1115"></joint>
                                                                    <geom class="robot0:D_Vizual" name="robot0:V_lfknuckle" mesh="robot0:knuckle"></geom>
                                                                    <body name="robot0:lfproximal" pos="0 0 0">
                                                                        <inertial pos="0 0 0.023" quat="0.707 -0.004 0.004 0.707" mass="0.014" diaginertia="1e-05 1e-05 1e-05"></inertial>
                                                                        <joint name="robot0:LFJ2" type="hinge" pos="0 0 0" axis="1 0 0" range="0 1.571" user="1114"></joint>
                                                                        <geom class="robot0:D_Vizual" name="robot0:V_lfproximal" mesh="robot0:F3"></geom>
                                                                        <geom class="robot0:DC_Hand" name="robot0:C_lfproximal" type="capsule" pos="0 0 0.0225" size="0.01 0.0225"></geom>
                                                                        <body name="robot0:lfmiddle" pos="0 0 0.045">
                                                                            <inertial pos="0 0 0.012" quat="0.707 0 0 0.707" mass="0.012" diaginertia="1e-05 1e-05 1e-05"></inertial>
                                                                            <joint name="robot0:LFJ1" type="hinge" pos="0 0 0" axis="1 0 0" range="0 1.571" user="1113"></joint>
                                                                            <geom class="robot0:D_Vizual" name="robot0:V_lfmiddle" mesh="robot0:F2"></geom>
                                                                            <geom class="robot0:DC_Hand" name="robot0:C_lfmiddle" type="capsule" pos="0 0 0.0125" size="0.00805 0.0125"></geom>
                                                                            <body name="robot0:lfdistal" pos="0 0 0.025">
                                                                                <inertial pos="0 0 0.015" quat="0.707 -0.003 0.003 0.707" mass="0.01" diaginertia="1e-05 1e-05 1e-05"></inertial>
                                                                                <joint name="robot0:LFJ0" type="hinge" pos="0 0 0" axis="1 0 0" range="0 1.571" user="1112"></joint>
                                                                                <geom class="robot0:D_Vizual" name="robot0:V_lfdistal" mesh="robot0:F1" pos="0 0 0.001"></geom>
                                                                                <geom class="robot0:DC_Hand" name="robot0:C_lfdistal" type="capsule" pos="0 0 0.012" size="0.00705 0.012" condim="4"></geom>
                                                                                <site name="robot0:S_lftip" pos="0 0 0.026" group="3"></site>
                                                                                <site class="robot0:D_Touch" name="robot0:Tch_lftip"></site>
                                                                            </body>
                                                                        </body>
                                                                    </body>
                                                                </body>
                                                            </body>
                                                            <body name="robot0:thbase" pos="0.034 -0.009 0.029" axisangle="0 1 0 0.785">
                                                                <inertial pos="0 0 0" mass="0.01" diaginertia="1e-05 1e-05 1e-05"></inertial>
                                                                <joint name="robot0:THJ4" type="hinge" pos="0 0 0" axis="0 0 -1" range="-1.047 1.047" user="1121"></joint>
                                                                <geom name="robot0:V_thbase" type="box" group="1" pos="0 0 0" size="0.001 0.001 0.001"></geom>
                                                                <body name="robot0:thproximal" pos="0 0 0">
                                                                    <inertial pos="0 0 0.017" quat="0.982 0 0.001 0.191" mass="0.016" diaginertia="1e-05 1e-05 1e-05"></inertial>
                                                                    <joint name="robot0:THJ3" type="hinge" pos="0 0 0" axis="1 0 0" range="0 1.222" user="1120"></joint>
                                                                    <geom class="robot0:D_Vizual" name="robot0:V_thproximal" mesh="robot0:TH3_z"></geom>
                                                                    <geom class="robot0:DC_Hand" name="robot0:C_thproximal" type="capsule" pos="0 0 0.019" size="0.013 0.019" rgba="0.4 0.5 0.6 0.1"></geom>
                                                                    <body name="robot0:thhub" pos="0 0 0.038">
                                                                        <inertial pos="0 0 0" mass="0.002" diaginertia="1e-05 1e-05 1e-05"></inertial>
                                                                        <joint name="robot0:THJ2" type="hinge" pos="0 0 0" axis="1 0 0" range="-0.209 0.209" user="1119"></joint>
                                                                        <geom name="robot0:V_thhub" type="box" group="1" pos="0 0 0" size="0.001 0.001 0.001"></geom>
                                                                        <body name="robot0:thmiddle" pos="0 0 0">
                                                                            <inertial pos="0 0 0.016" quat="1 -0.001 -0.007 0.003" mass="0.016" diaginertia="1e-05 1e-05 1e-05"></inertial>
                                                                            <joint name="robot0:THJ1" type="hinge" pos="0 0 0" axis="0 1 0" range="-0.524 0.524" user="1118"></joint>
                                                                            <geom class="robot0:D_Vizual" name="robot0:V_thmiddle" mesh="robot0:TH2_z"></geom>
                                                                            <geom class="robot0:DC_Hand" name="robot0:C_thmiddle" type="capsule" pos="0 0 0.016" size="0.011 0.016"></geom>
                                                                            <body name="robot0:thdistal" pos="0 0 0.032">
                                                                                <inertial pos="0 0 0.016" quat="0.999 -0.005 -0.047 0.005" mass="0.016" diaginertia="1e-05 1e-05 1e-05"></inertial>
                                                                                <joint name="robot0:THJ0" type="hinge" pos="0 0 0" axis="0 1 0" range="-1.571 0" user="1117"></joint>
                                                                                <geom class="robot0:D_Vizual" name="robot0:V_thdistal" mesh="robot0:TH1_z"></geom>
                                                                                <geom class="robot0:DC_Hand" name="robot0:C_thdistal" type="capsule" pos="0 0 0.013" size="0.00918 0.013" condim="4"></geom>
                                                                                <site name="robot0:S_thtip" pos="0 0 0.0275" group="3"></site>
                                                                                <site class="robot0:D_Touch" name="robot0:Tch_thtip" size="0.005 0.011 0.016" pos="-0.005 0 0.02"></site>
                                                                            </body>
                                                                        </body>
                                                                    </body>
                                                                </body>
                                                            </body>
                                                        </body>
                                                    </body>
                                                </body>
                                            </body>
											<body name="robot0:gripper_camera_link" pos="0.055 0 0.0225">
												<body name="robot0:gripper_camera_rgb_frame" pos="0 0.02 0">
													<body name="robot0:gripper_camera_rgb_optical_frame" pos="0 0 0" quat="0.5 -0.5 0.5 -0.5">
														<camera euler="3.1415 0 0" fovy="50" name="gripper_camera_rgb" pos="0 0 0"></camera>
													</body>
												</body>
												<body name="robot0:gripper_camera_depth_frame" pos="0 0.045 0">
													<body name="robot0:gripper_camera_depth_optical_frame" pos="0 0 0" quat="0.5 -0.5 0.5 -0.5"></body>
												</body>
											</body>
											<site name="robot0:grip" pos="0.02 0 0" rgba="0 0 0 0" size="0.02 0.02 0.02"></site>
										</body>
									</body>
								</body>
							</body>
						</body>
					</body>
				</body>
			</body>
		</body>
		<body name="robot0:estop_link" pos="-0.1246 0.2389 0.3113" quat="0.7071 0.7071 0 0">
			<inertial diaginertia="0 0 0" mass="0.002" pos="0.0024 -0.0033 0.0067" quat="0.3774 -0.1814 0.1375 0.8977"></inertial>
			<geom mesh="robot0:estop_link" rgba="0.8 0 0 1" name="robot0:estop_link"></geom>
		</body>
		<body name="robot0:laser_link" pos="0.235 0 0.2878" quat="0 1 0 0">
			<inertial diaginertia="0 0 0" mass="0.0083" pos="-0.0306 0.0007 0.0552" quat="0.5878 0.5378 -0.4578 0.3945"></inertial>
			<geom mesh="robot0:laser_link" rgba="0.7922 0.8196 0.9333 1" name="robot0:laser_link"></geom>
			<camera euler="1.55 -1.55 3.14" fovy="25" name="lidar" pos="0 0 0.02"></camera>
		</body>
		<body name="robot0:torso_fixed_link" pos="-0.0869 0 0.3774">
			<inertial diaginertia="0.3865 0.3394 0.1009" mass="13.2775" pos="-0.0722 0.0057 0.2656" quat="0.9995 0.0249 0.0177 0.011"></inertial>
			<geom mesh="robot0:torso_fixed_link" name="robot0:torso_fixed_link" class="robot0:blue"></geom>
		</body>
		<body name="robot0:external_camera_body_0" pos="0 0 0">
			<camera euler="0 0.75 1.57" fovy="43.3" name="external_camera_0" pos="1.3 0 1.2"></camera>
		</body>
	</body>
</mujoco>
