<mujoco>
	<body mocap="true" name="robot0:mocap" pos="0 0 0">
		<geom conaffinity="0" contype="0" pos="0 0 0" rgba="0 0.5 0 0.0" size="0.005 0.005 0.005" type="box"></geom>
	</body>

	<body name="robot0">
		<joint name="basejoint" type="free" limited="false" damping="0.01"></joint>
		<body name="robot0:SeaClearRobotUpper" euler="0 0 0" pos="0.03 0 0.65">
			<geom mesh="seaclear_robot_upper" margin="0.001" rgba="1. 0.65 0.0 1.0" conaffinity="0" contype="0" type="mesh" user="0"></geom>
		</body>
		<body name="robot0:SeaClearRobotLower" euler="0 0 0" pos="0.03 0 0.65">
			<geom mesh="seaclear_robot_lower" margin="0.001" rgba=".2 .2 .2 1" conaffinity="0" contype="0" type="mesh" user="0"></geom>
		</body>

		<body euler="0 0 0" name="robot0:gripper_link" pos="0 0 0.45">
			<body childclass="robot0:SeaClearGripper" name="robot0:r_gripper_finger_link" pos="0.01 -0.0015 0" euler="1.5707 0 0">
				<inertial diaginertia="0.1 0.1 0.1" mass="4" pos="0 0 0"></inertial>
				<joint axis="0 0 1" name="robot0:r_gripper_finger_joint" range="0 1.5707"></joint>
				<geom mesh="seaclear_gripper_link" type="mesh" name="robot0:r_gripper_finger_link" conaffinity="0" contype="0" rgba="1. 0.65 0.0 1.0"></geom>
				<geom type="box" size="0.043071 0.002 0.1" pos="0.030462 -0.268919 0"></geom>
				<geom type="box" size="0.01326 0.002 0.1" pos="0.085006 -0.259599 0" euler="0 0 0.602"></geom>
				<geom type="box" size="0.01326 0.002 0.1" pos="0.102672 -0.241337 0" euler="0 0 0.999"></geom>
				<geom type="box" size="0.014 0.002 0.1" pos="0.110072 -0.21551 0" euler="0 0 1.557"></geom>
				<geom type="box" size="0.09 0.002 0.1" pos="0.073909 -0.117968 0" euler="0 0 1.977"></geom>
				<geom type="box" size="0.02514 0.002 0.115029" pos="0.013511 -0.153393 0.096056" euler="1.5708 0 0"></geom>
				<geom type="box" size="0.02514 0.002 0.085029" pos="0.051662 -0.124861 0.096056" euler="1.5708 0.402 0"></geom>
				<geom type="cylinder" size="0.05 0.002" pos="0.063914 -0.215517 0.096119"></geom>
				<geom type="box" size="0.02514 0.002 0.115029" pos="0.013511 -0.153393 -0.098" euler="1.5708 0 0"></geom>
				<geom type="box" size="0.02514 0.002 0.085029" pos="0.051662 -0.124861 -0.098" euler="1.5708 0.402 0"></geom>
				<geom type="cylinder" size="0.05 0.002" pos="0.063914 -0.215517 -0.098"></geom>
			</body>
			<body childclass="robot0:SeaClearGripper" name="robot0:l_gripper_finger_link" pos="-0.01 0.0015 0" euler="1.5707 3.1416 0">
				<inertial diaginertia="0.1 0.1 0.1" mass="1" pos="0 0 0"></inertial>
				<joint axis="0 0 1" name="robot0:l_gripper_finger_joint" range="0 1.5707"></joint>
				<geom mesh="seaclear_gripper_link" type="mesh" name="robot0:l_gripper_finger_link" conaffinity="0" contype="0" rgba="1. 0.65 0.0 1.0"></geom>
				<geom type="box" size="0.043071 0.002 0.1" pos="0.030462 -0.268919 0"></geom>
				<geom type="box" size="0.01326 0.002 0.1" pos="0.085006 -0.259599 0" euler="0 0 0.602"></geom>
				<geom type="box" size="0.01326 0.002 0.1" pos="0.102672 -0.241337 0" euler="0 0 0.999"></geom>
				<geom type="box" size="0.014 0.002 0.1" pos="0.110072 -0.21551 0" euler="0 0 1.557"></geom>
				<geom type="box" size="0.09 0.002 0.1" pos="0.073909 -0.117968 0" euler="0 0 1.977"></geom>
				<geom type="box" size="0.02514 0.002 0.115029" pos="0.013511 -0.153393 0.096056" euler="1.5708 0 0"></geom>
				<geom type="box" size="0.02514 0.002 0.085029" pos="0.051662 -0.124861 0.096056" euler="1.5708 0.402 0"></geom>
				<geom type="cylinder" size="0.05 0.002" pos="0.063914 -0.215517 0.096119"></geom>
				<geom type="box" size="0.02514 0.002 0.115029" pos="0.013511 -0.153393 -0.098" euler="1.5708 0 0"></geom>
				<geom type="box" size="0.02514 0.002 0.085029" pos="0.051662 -0.124861 -0.098" euler="1.5708 0.402 0"></geom>
				<geom type="cylinder" size="0.05 0.002" pos="0.063914 -0.215517 -0.098"></geom>
			</body>
			<site name="robot0:grip" pos="0 0 0" rgba="0 0 0 0" size="0.02 0.02 0.02"></site>
		</body>
	</body>
</mujoco>
